traceback: Traceback (most recent call last):
  File "Z:\D\DESKTOP\programmer2\branches\programmer_py3\src\workers.py", line 71, in run
  File "Z:\D\DESKTOP\programmer2\branches\programmer_py3\src\workers.py", line 137, in jobs_ftdi
  File "Z:\D\DESKTOP\programmer2\branches\programmer_py3\src\workers.py", line 256, in job_running
  File "Z:\D\DESKTOP\programmer2\branches\programmer_py3\src\workers.py", line 1270, in exec_operation
  File "Z:\D\DESKTOP\programmer2\branches\programmer_py3\src\jtag_mode.py", line 4301, in sector_erase
  File "Z:\D\DESKTOP\programmer2\branches\programmer_py3\src\jtag_mode.py", line 4356, in spiBusy
  File "E:\workspace\GoAI\programmer1.9.7.01(build1231).Win32.x86\programmer2\bin\data\resource\resource.zip\ftd2xx\ftd2xx.py", line 157, in read
    call_ft(_ft.FT_Read, self.handle, b, nchars, c.byref(b_read))
  File "E:\workspace\GoAI\programmer1.9.7.01(build1231).Win32.x86\programmer2\bin\data\resource\resource.zip\ftd2xx\ftd2xx.py", line 41, in call_ft
    raise DeviceError(status)
ftd2xx.ftd2xx.DeviceError: IO_ERROR
